I'm sorry, but an uncaught exception occurred.

While running game code:
  File "game/script.rpy", line 1989, in script
    m1 "I think we've seen enough. It's time to get off the stage."
Exception: Sayer 'm1' is not defined.

-- Full Traceback ------------------------------------------------------------

Full traceback:
  File "game/script.rpy", line 1989, in script
    m1 "I think we've seen enough. It's time to get off the stage."
  File "renpy/ast.py", line 680, in execute
    who = eval_who(self.who, self.who_fast)
  File "renpy/ast.py", line 574, in eval_who
    raise Exception("Sayer '%s' is not defined." % who)
Exception: Sayer 'm1' is not defined.

Windows-10-10.0.17763
Ren'Py 7.4.4.1439
The Thief, the Toad, the Witch & the Mushroom 1.0
Fri Nov 26 15:01:32 2021
