I'm sorry, but an uncaught exception occurred.

While running game code:
  File "game/script.rpy", line 5426, in script
    Goblin4 "Aye, boss!"
Exception: Sayer 'Goblin4' is not defined.

-- Full Traceback ------------------------------------------------------------

Full traceback:
  File "game/script.rpy", line 5426, in script
    Goblin4 "Aye, boss!"
  File "renpy/ast.py", line 680, in execute
    who = eval_who(self.who, self.who_fast)
  File "renpy/ast.py", line 574, in eval_who
    raise Exception("Sayer '%s' is not defined." % who)
Exception: Sayer 'Goblin4' is not defined.

Windows-10-10.0.19041
Ren'Py 7.4.4.1439
Lacuna. 0.81
Fri Dec  9 11:14:38 2022
